<sdf version='1.11'>
  <model name='ur3e_2fg7_l515'>

    <link name='base_link'>
      <inertial>
        <pose>0 0 0 0 0 0</pose>
        <mass>2</mass>
        <inertia>
          <ixx>0.0030531654453999999</ixx>
          <ixy>0</ixy>
          <ixz>0</ixz>
          <iyy>0.0030531654453999999</iyy>
          <iyz>0</iyz>
          <izz>0.0056249999999999998</izz>
        </inertia>
      </inertial>
      <collision name='base_link_inertia_collision'>
        <pose>0 0 0 0 0 -2.4492935982947059e-16</pose>
        <geometry>
          <mesh>
            <scale>1 1 1</scale>
            <uri>/opt/ros/jazzy/share/ur_description/meshes/ur3e/collision/base.stl</uri>
          </mesh>
        </geometry>
      </collision>
      <visual name='base_link_inertia_visual'>
        <pose>0 0 0 0 0 -2.4492935982947059e-16</pose>
        <geometry>
          <mesh>
            <scale>1 1 1</scale>
            <uri>/opt/ros/jazzy/share/ur_description/meshes/ur3e/visual/base.dae</uri>
          </mesh>
        </geometry>
        <material>
          <diffuse>0.875 0.875 0.875 1</diffuse>
          <ambient>0.875 0.875 0.875 1</ambient>
        </material>
      </visual>
    </link>

    <joint name='shoulder_pan_joint' type='revolute'>
      <pose relative_to='base_link'>0 0 0.15185000000000001 0 0 3.1415926535897931</pose>
      <parent>base_link</parent>
      <child>shoulder_link</child>
      <axis>
        <xyz>0 0 1</xyz>
        <limit>
          <lower>-6.2831853071795862</lower>
          <upper>6.2831853071795862</upper>
          <effort>56</effort>
          <velocity>3.1415926535897931</velocity>
        </limit>
        <dynamics>
          <damping>0</damping>
          <friction>0</friction>
          <spring_reference>0</spring_reference>
          <spring_stiffness>0</spring_stiffness>
        </dynamics>
      </axis>
    </joint>

    <link name='shoulder_link'>
      <pose relative_to='shoulder_pan_joint'>0 0 0 0 0 0</pose>
      <inertial>
        <pose>0 0 0 0 0 0</pose>
        <mass>2</mass>
        <inertia>
          <ixx>0.0080931634293999986</ixx>
          <ixy>0</ixy>
          <ixz>0</ixz>
          <iyy>0.0080931634293999986</iyy>
          <iyz>0</iyz>
          <izz>0.0056249999999999998</izz>
        </inertia>
      </inertial>
      <collision name='shoulder_link_collision'>
        <pose>0 0 0 0 0 3.1415926535897931</pose>
        <geometry>
          <mesh>
            <scale>1 1 1</scale>
            <uri>/opt/ros/jazzy/share/ur_description/meshes/ur3e/collision/shoulder.stl</uri>
          </mesh>
        </geometry>
      </collision>
      <visual name='shoulder_link_visual'>
        <pose>0 0 0 0 0 3.1415926535897931</pose>
        <geometry>
          <mesh>
            <scale>1 1 1</scale>
            <uri>/opt/ros/jazzy/share/ur_description/meshes/ur3e/visual/shoulder.dae</uri>
          </mesh>
        </geometry>
        <material>
          <diffuse>0.875 0.875 0.875 1</diffuse>
          <ambient>0.875 0.875 0.875 1</ambient>
        </material>
      </visual>
    </link>

    <joint name='shoulder_lift_joint' type='revolute'>
      <pose relative_to='shoulder_link'>0 0 0 1.5707963270000003 0 0</pose>
      <parent>shoulder_link</parent>
      <child>upper_arm_link</child>
      <axis>
        <xyz>0 0 1</xyz>
        <limit>
          <lower>-6.2831853071795862</lower>
          <upper>6.2831853071795862</upper>
          <effort>56</effort>
          <velocity>3.1415926535897931</velocity>
        </limit>
        <dynamics>
          <damping>0</damping>
          <friction>0</friction>
          <spring_reference>0</spring_reference>
          <spring_stiffness>0</spring_stiffness>
        </dynamics>
      </axis>
    </joint>

    <link name='upper_arm_link'>
      <pose relative_to='shoulder_lift_joint'>0 0 0 0 0 0</pose>
      <inertial>
        <pose>-0.121825 0 0.12 0 1.5707963267948966 0</pose>
        <mass>3.4199999999999999</mass>
        <inertia>
          <ixx>0.021728483221103229</ixx>
          <ixy>0</ixy>
          <ixz>0</ixz>
          <iyy>0.021728483221103229</iyy>
          <iyz>0</iyz>
          <izz>0.0096187500000000006</izz>
        </inertia>
      </inertial>
      <collision name='upper_arm_link_collision'>
        <pose>0 0 0.12 1.5707963267948959 5.5511151231257827e-17 -1.5707963267948959</pose>
        <geometry>
          <mesh>
            <scale>1 1 1</scale>
            <uri>/opt/ros/jazzy/share/ur_description/meshes/ur3e/collision/upperarm.stl</uri>
          </mesh>
        </geometry>
      </collision>
      <visual name='upper_arm_link_visual'>
        <pose>0 0 0.12 1.5707963267948959 5.5511151231257827e-17 -1.5707963267948959</pose>
        <geometry>
          <mesh>
            <scale>1 1 1</scale>
            <uri>/opt/ros/jazzy/share/ur_description/meshes/ur3e/visual/upperarm.dae</uri>
          </mesh>
        </geometry>
        <material>
          <diffuse>0.875 0.875 0.875 1</diffuse>
          <ambient>0.875 0.875 0.875 1</ambient>
        </material>
      </visual>
    </link>

    <joint name='elbow_joint' type='revolute'>
      <pose relative_to='upper_arm_link'>-0.24354999999999999 0 0 0 0 0</pose>
      <parent>upper_arm_link</parent>
      <child>forearm_link</child>
      <axis>
        <xyz>0 0 1</xyz>
        <limit>
          <lower>-3.1415926535897931</lower>
          <upper>3.1415926535897931</upper>
          <effort>28</effort>
          <velocity>3.1415926535897931</velocity>
        </limit>
        <dynamics>
          <damping>0</damping>
          <friction>0</friction>
          <spring_reference>0</spring_reference>
          <spring_stiffness>0</spring_stiffness>
        </dynamics>
      </axis>
    </joint>

    <link name='forearm_link'>
      <pose relative_to='elbow_joint'>0 0 0 0 0 0</pose>
      <inertial>
        <pose>-0.1066 0 0.027 0 1.5707963267948966 0</pose>
        <mass>1.26</mass>
        <inertia>
          <ixx>0.0065445675821719186</ixx>
          <ixy>0</ixy>
          <ixz>0</ixz>
          <iyy>0.0065445675821719186</iyy>
          <iyz>0</iyz>
          <izz>0.00354375</izz>
        </inertia>
      </inertial>
      <collision name='forearm_link_collision'>
        <pose>0 0 0.027 1.5707963267948959 5.5511151231257827e-17 -1.5707963267948959</pose>
        <geometry>
          <mesh>
            <scale>1 1 1</scale>
            <uri>/opt/ros/jazzy/share/ur_description/meshes/ur3e/collision/forearm.stl</uri>
          </mesh>
        </geometry>
      </collision>
      <visual name='forearm_link_visual'>
        <pose>0 0 0.027 1.5707963267948959 5.5511151231257827e-17 -1.5707963267948959</pose>
        <geometry>
          <mesh>
            <scale>1 1 1</scale>
            <uri>/opt/ros/jazzy/share/ur_description/meshes/ur3e/visual/forearm.dae</uri>
          </mesh>
        </geometry>
        <material>
          <diffuse>0.875 0.875 0.875 1</diffuse>
          <ambient>0.875 0.875 0.875 1</ambient>
        </material>
      </visual>
    </link>

    <joint name='wrist_1_joint' type='revolute'>
      <pose relative_to='forearm_link'>-0.2132 0 0.13105 0 0 0</pose>
      <parent>forearm_link</parent>
      <child>wrist_1_link</child>
      <axis>
        <xyz>0 0 1</xyz>
        <limit>
          <lower>-6.2831853071795862</lower>
          <upper>6.2831853071795862</upper>
          <effort>12</effort>
          <velocity>6.2831853071795862</velocity>
        </limit>
        <dynamics>
          <damping>0</damping>
          <friction>0</friction>
          <spring_reference>0</spring_reference>
          <spring_stiffness>0</spring_stiffness>
        </dynamics>
      </axis>
    </joint>

    <link name='wrist_1_link'>
      <pose relative_to='wrist_1_joint'>0 0 0 0 0 0</pose>
      <inertial>
        <pose>0 0 0 0 0 0</pose>
        <mass>0.80000000000000004</mass>
        <inertia>
          <ixx>0.0020849991659999999</ixx>
          <ixy>0</ixy>
          <ixz>0</ixz>
          <iyy>0.0020849991659999999</iyy>
          <iyz>0</iyz>
          <izz>0.0022499999999999998</izz>
        </inertia>
      </inertial>
      <collision name='wrist_1_link_collision'>
        <pose>0 0 -0.104 1.5707963267948959 0 0</pose>
        <geometry>
          <mesh>
            <scale>1 1 1</scale>
            <uri>/opt/ros/jazzy/share/ur_description/meshes/ur3e/collision/wrist1.stl</uri>
          </mesh>
        </geometry>
      </collision>
      <visual name='wrist_1_link_visual'>
        <pose>0 0 -0.104 1.5707963267948959 0 0</pose>
        <geometry>
          <mesh>
            <scale>1 1 1</scale>
            <uri>/opt/ros/jazzy/share/ur_description/meshes/ur3e/visual/wrist1.dae</uri>
          </mesh>
        </geometry>
        <material>
          <diffuse>0.875 0.875 0.875 1</diffuse>
          <ambient>0.875 0.875 0.875 1</ambient>
        </material>
      </visual>
    </link>

    <joint name='wrist_2_joint' type='revolute'>
      <pose relative_to='wrist_1_link'>0 -0.085349999999999995 -1.750557762378351e-11 1.5707963270000003 0 0</pose>
      <parent>wrist_1_link</parent>
      <child>wrist_2_link</child>
      <axis>
        <xyz>0 0 1</xyz>
        <limit>
          <lower>-6.2831853071795862</lower>
          <upper>6.2831853071795862</upper>
          <effort>12</effort>
          <velocity>6.2831853071795862</velocity>
        </limit>
        <dynamics>
          <damping>0</damping>
          <friction>0</friction>
          <spring_reference>0</spring_reference>
          <spring_stiffness>0</spring_stiffness>
        </dynamics>
      </axis>
    </joint>

    <link name='wrist_2_link'>
      <pose relative_to='wrist_2_joint'>0 0 0 0 0 0</pose>
      <inertial>
        <pose>0 0 0 0 0 0</pose>
        <mass>0.80000000000000004</mass>
        <inertia>
          <ixx>0.0020849991659999999</ixx>
          <ixy>0</ixy>
          <ixz>0</ixz>
          <iyy>0.0020849991659999999</iyy>
          <iyz>0</iyz>
          <izz>0.0022499999999999998</izz>
        </inertia>
      </inertial>
      <collision name='wrist_2_link_collision'>
        <pose>0 0 -0.085349999999999995 0 0 0</pose>
        <geometry>
          <mesh>
            <scale>1 1 1</scale>
            <uri>/opt/ros/jazzy/share/ur_description/meshes/ur3e/collision/wrist2.stl</uri>
          </mesh>
        </geometry>
      </collision>
      <visual name='wrist_2_link_visual'>
        <pose>0 0 -0.085349999999999995 0 0 0</pose>
        <geometry>
          <mesh>
            <scale>1 1 1</scale>
            <uri>/opt/ros/jazzy/share/ur_description/meshes/ur3e/visual/wrist2.dae</uri>
          </mesh>
        </geometry>
        <material>
          <diffuse>0.875 0.875 0.875 1</diffuse>
          <ambient>0.875 0.875 0.875 1</ambient>
        </material>
      </visual>
    </link>

    <joint name='wrist_3_joint' type='revolute'>
      <pose relative_to='wrist_2_link'>0 0.092100000000000001 -1.8890025766261998e-11 -1.5707963270000003 1.2246467991473527e-16 -1.224646799147353e-16</pose>
      <parent>wrist_2_link</parent>
      <child>wrist_3_link</child>
      <axis>
        <xyz>0 0 1</xyz>
        <limit>
          <lower>-6.2831853071795862</lower>
          <upper>6.2831853071795862</upper>
          <effort>12</effort>
          <velocity>6.2831853071795862</velocity>
        </limit>
        <dynamics>
          <damping>0</damping>
          <friction>0</friction>
          <spring_reference>0</spring_reference>
          <spring_stiffness>0</spring_stiffness>
        </dynamics>
      </axis>
    </joint>

    <link name='wrist_3_link'>
      <pose relative_to='wrist_3_joint'>0 0 0 0 0 0</pose>
      <inertial>
        <pose>-3.6132254669462912e-05 -0.0040803600481361113 0.045569886311495861 0 0 0</pose>
        <mass>1.7146523179240969</mass>
        <inertia>
          <ixx>0.0046578756007556767</ixx>
          <ixy>2.5297208278584472e-07</ixy>
          <ixz>-1.6034930286007489e-06</ixz>
          <iyy>0.0045044242132445218</iyy>
          <iyz>-0.00038907037827767008</iyz>
          <izz>0.001793652980591063</izz>
        </inertia>
      </inertial>
      <collision name='wrist_3_link_collision'>
        <pose>0 0 -0.092100000000000001 1.5707963267948959 0 0</pose>
        <geometry>
          <mesh>
            <scale>1 1 1</scale>
            <uri>/opt/ros/jazzy/share/ur_description/meshes/ur3e/collision/wrist3.stl</uri>
          </mesh>
        </geometry>
      </collision>
      <collision name='wrist_3_link_fixed_joint_lump__l515_base_collision_1'>
        <pose>1.387778780781446e-17 -0.070000000000000007 -0.009999999999999995 -2.4651903288156619e-32 -2.2204460492503131e-16 2.2204460492503131e-16</pose>
        <geometry>
          <cylinder>
            <length>0.040000000000000001</length>
            <radius>0.029999999999999999</radius>
          </cylinder>
        </geometry>
      </collision>
      <collision name='wrist_3_link_fixed_joint_lump__onrobot_2fg7_base_link_collision_2'>
        <pose>0 0 0 -2.4651903288156619e-32 -2.2204460492503131e-16 2.2204460492503131e-16</pose>
        <geometry>
          <mesh>
            <scale>0.001 0.001 0.001</scale>
            <uri>/home/jon/Workspace/swap_ws/install/ur_custom_description/share/ur_custom_description/meshes/base_link.stl</uri>
          </mesh>
        </geometry>
      </collision>
      <visual name='wrist_3_link_visual'>
        <pose>0 0 -0.092100000000000001 1.5707963267948959 0 0</pose>
        <geometry>
          <mesh>
            <scale>1 1 1</scale>
            <uri>/opt/ros/jazzy/share/ur_description/meshes/ur3e/visual/wrist3.dae</uri>
          </mesh>
        </geometry>
        <material>
          <diffuse>0.875 0.875 0.875 1</diffuse>
          <ambient>0.875 0.875 0.875 1</ambient>
        </material>
      </visual>
      <visual name='wrist_3_link_fixed_joint_lump__l515_base_visual_1'>
        <pose>1.387778780781446e-17 -0.070000000000000007 -0.009999999999999995 -2.4651903288156619e-32 -2.2204460492503131e-16 2.2204460492503131e-16</pose>
        <geometry>
          <cylinder>
            <length>0.040000000000000001</length>
            <radius>0.029999999999999999</radius>
          </cylinder>
        </geometry>
        <material>
          <diffuse>0 0 0 1</diffuse>
          <ambient>0 0 0 1</ambient>
        </material>
      </visual>
      <visual name='wrist_3_link_fixed_joint_lump__onrobot_2fg7_base_link_visual_2'>
        <pose>0 0 0 -2.4651903288156619e-32 -2.2204460492503131e-16 2.2204460492503131e-16</pose>
        <geometry>
          <mesh>
            <scale>0.001 0.001 0.001</scale>
            <uri>/home/jon/Workspace/swap_ws/install/ur_custom_description/share/ur_custom_description/meshes/base_link.stl</uri>
          </mesh>
        </geometry>
        <material>
          <diffuse>0.875 0.875 0.875 1</diffuse>
          <ambient>0.875 0.875 0.875 1</ambient>
        </material>
      </visual>
    </link>

    <joint name='left_finger_joint' type='prismatic'>
      <pose relative_to='wrist_3_link'>0.032238999999999983 -0.029493999999999999 0.12005 -2.4651903288156619e-32 -2.2204460492503131e-16 2.2204460492503131e-16</pose>
      <parent>wrist_3_link</parent>
      <child>left_finger_link</child>
      <axis>
        <xyz>-1 0 0</xyz>
        <limit>
          <lower>0</lower>
          <upper>0.019</upper>
          <effort>140</effort>
          <velocity>0.45000000000000001</velocity>
        </limit>
        <dynamics>
          <spring_reference>0</spring_reference>
          <spring_stiffness>0</spring_stiffness>
        </dynamics>
      </axis>
    </joint>

    <link name='left_finger_link'>
      <pose relative_to='left_finger_joint'>0 0 0 0 0 0</pose>
      <inertial>
        <pose>0.0042477033221197391 0.029496959480080669 0.01523421548623795 0 0 0</pose>
        <mass>0.023219383355922291</mass>
        <inertia>
          <ixx>6.0000000000000002e-06</ixx>
          <ixy>0</ixy>
          <ixz>-9.9999999999999995e-07</ixz>
          <iyy>5.0000000000000004e-06</iyy>
          <iyz>0</iyz>
          <izz>1.9999999999999999e-06</izz>
        </inertia>
      </inertial>
      <collision name='left_finger_link_fixed_joint_lump__left_finger_collision_collision'>
        <pose>-0.032238999999999997 0.029493999999999999 -0.12005 0 0 0</pose>
        <geometry>
          <mesh>
            <scale>0.001 0.001 0.001</scale>
            <uri>/home/jon/Workspace/swap_ws/install/ur_custom_description/share/ur_custom_description/meshes/left_finger_link.stl</uri>
          </mesh>
        </geometry>
      </collision>
      <visual name='left_finger_link_visual'>
        <pose>-0.032238999999999997 0.029493999999999999 -0.12005 0 0 0</pose>
        <geometry>
          <mesh>
            <scale>0.001 0.001 0.001</scale>
            <uri>/home/jon/Workspace/swap_ws/install/ur_custom_description/share/ur_custom_description/meshes/left_finger_link.stl</uri>
          </mesh>
        </geometry>
        <material>
          <diffuse>0.875 0.875 0.875 1</diffuse>
          <ambient>0.875 0.875 0.875 1</ambient>
        </material>
      </visual>
    </link>

    <joint name='right_finger_joint' type='prismatic'>
      <pose relative_to='wrist_3_link'>-0.05436100000000002 -0.029494000000000031 0.12005 -2.4651903288156619e-32 -2.2204460492503131e-16 2.2204460492503131e-16</pose>
      <parent>wrist_3_link</parent>
      <child>right_finger_link</child>
      <axis>
        <xyz>1 0 0</xyz>
        <!--
        <mimic joint='left_finger_joint'>
          <multiplier>1</multiplier>
          <offset>0</offset>
          <reference>0</reference>
        </mimic>
        -->
        <limit>
          <lower>-0.019</lower>
          <upper>0.019</upper>
          <effort>140</effort>
          <velocity>0.45000000000000001</velocity>
        </limit>
        <dynamics>
          <spring_reference>0</spring_reference>
          <spring_stiffness>0</spring_stiffness>
        </dynamics>
      </axis>
    </joint>

    <link name='right_finger_link'>
      <pose relative_to='right_finger_joint'>0 0 0 0 0 0</pose>
      <inertial>
        <pose>0.017874296677847162 0.02949104051991925 0.015234215486228289 0 0 0</pose>
        <mass>0.023219383355922291</mass>
        <inertia>
          <ixx>6.0000000000000002e-06</ixx>
          <ixy>0</ixy>
          <ixz>9.9999999999999995e-07</ixz>
          <iyy>5.0000000000000004e-06</iyy>
          <iyz>0</iyz>
          <izz>1.9999999999999999e-06</izz>
        </inertia>
      </inertial>
      <collision name='right_finger_link_fixed_joint_lump__right_finger_collision_collision'>
        <pose>0.054361 0.029493999999999999 -0.12005 0 0 0</pose>
        <geometry>
          <mesh>
            <scale>0.001 0.001 0.001</scale>
            <uri>/home/jon/Workspace/swap_ws/install/ur_custom_description/share/ur_custom_description/meshes/right_finger_link.stl</uri>
          </mesh>
        </geometry>
      </collision>
      <visual name='right_finger_link_visual'>
        <pose>0.054361 0.029493999999999999 -0.12005 0 0 0</pose>
        <geometry>
          <mesh>
            <scale>0.001 0.001 0.001</scale>
            <uri>/home/jon/Workspace/swap_ws/install/ur_custom_description/share/ur_custom_description/meshes/right_finger_link.stl</uri>
          </mesh>
        </geometry>
        <material>
          <diffuse>0.875 0.875 0.875 1</diffuse>
          <ambient>0.875 0.875 0.875 1</ambient>
        </material>
      </visual>
    </link>

    <frame name='base_link-base_fixed_joint' attached_to='base_link'>
      <pose>0 0 0 0 0 3.1415926535897931</pose>
    </frame>

    <frame name='base' attached_to='base_link-base_fixed_joint'>
      <pose>0 0 0 0 0 0</pose>
    </frame>

    <frame name='base_link-base_link_inertia' attached_to='base_link'>
      <pose>0 0 0 0 0 3.1415926535897931</pose>
    </frame>

    <frame name='base_link_inertia' attached_to='base_link-base_link_inertia'>
      <pose>0 0 0 0 0 0</pose>
    </frame>

    <frame name='gripper_to_l515' attached_to='tool0'>
      <pose>0 0 0 0 0 0</pose>
    </frame>

    <frame name='l515_base' attached_to='gripper_to_l515'>
      <pose>0 0 0 0 0 0</pose>
    </frame>

    <frame name='world_joint' attached_to='tool0'>
      <pose>0 0 0 0 0 0</pose>
    </frame>

    <frame name='onrobot_2fg7_base_link' attached_to='world_joint'>
      <pose>0 0 0 0 0 0</pose>
    </frame>

    <frame name='flange-tool0' attached_to='flange'>
      <pose>0 0 0 1.5707963267948959 -5.5511151231257827e-17 1.5707963267948959</pose>
    </frame>

    <frame name='tool0' attached_to='flange-tool0'>
      <pose>0 0 0 0 0 0</pose>
    </frame>

    <frame name='wrist_3-flange' attached_to='wrist_3_link'>
      <pose>0 0 0 -1.5707963267948957 -1.5707963267948966 0</pose>
    </frame>

    <frame name='flange' attached_to='wrist_3-flange'>
      <pose>0 0 0 0 0 0</pose>
    </frame>

  </model>
</sdf>
