<?xml version="1.0" ?>
<robot name="2fg7_outwards">

  <material name="silver">
    <color rgba="0.700 0.700 0.700 1.000"/>
  </material>

  <link name="onrobot_2fg7_base_link">
    <inertial>
      <origin rpy="0 0 0" xyz="-4.898915958379213e-05 2.84756960271082e-06 0.06811082379774974"/>
      <mass value="1.2646523179240972"/>
      <inertia ixx="0.001504" ixy="-0.0" ixz="-3e-06" iyy="0.001812" iyz="0.0" izz="0.001053"/>
    </inertial>
    <visual>
      <origin rpy="0 0 0" xyz="0 0 0"/>
      <geometry>
        <mesh filename="package://ur_custom_description/meshes/base_link.stl" scale="0.001 0.001 0.001"/>
      </geometry>
      <material name="silver"/>
    </visual>
    <collision>
      <origin rpy="0 0 0" xyz="0 0 0"/>
      <geometry>
        <mesh filename="package://ur_custom_description/meshes/base_link.stl" scale="0.001 0.001 0.001"/>
      </geometry>
    </collision>
  </link>

  <link name="right_finger_link">
    <inertial>
      <origin rpy="0 0 0" xyz="0.017874296677847158 0.02949104051991925 0.01523421548622829"/>
      <mass value="0.023219383355922288"/>
      <inertia ixx="6e-06" ixy="-0.0" ixz="1e-06" iyy="5e-06" iyz="-0.0" izz="2e-06"/>
    </inertial>
    <visual>
      <origin rpy="0 0 0" xyz="0.054361 0.029494 -0.12005"/>
      <geometry>
        <mesh filename="package://ur_custom_description/meshes/right_finger_link.stl" scale="0.001 0.001 0.001"/>
      </geometry>
      <material name="silver"/>
    </visual>
    <collision name="right_finger_collision">
      <origin rpy="0 0 0" xyz="0.054361 0.029494 -0.12005"/>
      <geometry>
        <mesh filename="package://ur_custom_description/meshes/right_finger_link.stl" scale="0.001 0.001 0.001"/>
      </geometry>
    </collision>
  </link>

  <link name="left_finger_link">
    <inertial>
      <origin rpy="0 0 0" xyz="0.004247703322119739 0.029496959480080673 0.015234215486237948"/>
      <mass value="0.023219383355922288"/>
      <inertia ixx="6e-06" ixy="-0.0" ixz="-1e-06" iyy="5e-06" iyz="0.0" izz="2e-06"/>
    </inertial>
    <visual>
      <origin rpy="0 0 0" xyz="-0.032239 0.029494 -0.12005"/>
      <geometry>
        <mesh filename="package://ur_custom_description/meshes/left_finger_link.stl" scale="0.001 0.001 0.001"/>
      </geometry>
      <material name="silver"/>
    </visual>
    <collision name="left_finger_collision">
      <origin rpy="0 0 0" xyz="-0.032239 0.029494 -0.12005"/>
      <geometry>
        <mesh filename="package://ur_custom_description/meshes/left_finger_link.stl" scale="0.001 0.001 0.001"/>
      </geometry>
    </collision>
  </link>

  <joint name="left_finger_joint" type="prismatic">
    <origin rpy="0 0 0" xyz="0.032239 -0.029494 0.12005"/>
    <parent link="onrobot_2fg7_base_link"/>
    <child link="left_finger_link"/>
    <axis xyz="-1.0 0.0 0.0"/>
    <limit effort="140" lower="0.0" upper="0.019" velocity="0.45"/>
    <!-- total 0.38 -->
  </joint>

  <joint name="right_finger_joint" type="prismatic">
    <origin rpy="0 0 0" xyz="-0.054361 -0.029494 0.12005"/>
    <parent link="onrobot_2fg7_base_link"/>
    <child link="right_finger_link"/>
    <axis xyz="1.0 0.0 0.0"/>
    <limit effort="140" lower="-0.019" upper="0.019" velocity="0.45"/>
    <mimic joint="left_finger_joint" multiplier="1.0"/>
  </joint>

  <!-- <link name="base_link"/> -->
  <joint name="world_joint" type="fixed">
    <parent link="tool0"/>
    <child link="onrobot_2fg7_base_link"/>
    <origin rpy="0.0 0.0 0.0" xyz="0.0 0.0 0.0"/>
  </joint>

</robot>